Workbook

Sheet Start here
B2: The Money Mirror
B3: A tool for clarity. About 10 minutes, once. Then one minute a week.
B4: Pink boxes are yours to fill. Everything else updates itself.
B5: Before you start: File → Settings → Locale → your country. Then dates work the way you write them.
B7: 1 | C7: What's your first name? | E7: =IF(D7<>"","✓ done","")
B9: 2 | C9: What's in your business account today? | E9: =IF(D9<>"","✓ done","")
C10: Tip: this is just your starting point. Your money minute keeps it fresh.
B11: 3 | C11: Add your fixed costs, monthly or yearly → 'Fixed costs' tab | E11: =IF(COUNT('Fixed costs'!C8:C107)>0,"✓ done","")
C12: Rent on the 1st every month? Insurance on 26 July every year? Both go here.
B13: 4 | C13: Add anything people owe you → 'Owed to you' tab | E13: =IF(OR(COUNT('Owed to you'!C8:C107)>0,D14="Yes"),"✓ done","")
C14: Nobody owes me right now? Pick Yes →
B15: 5 | C15: Tax: what % of income do you set aside? | E15: =IF(D15<>"","✓ done","")
C16: Comfort cushion: an amount you never want to dip below
C17: If you already move tax to a separate account, put 0% above.
C20: =COUNTIF(E7:E15,"✓ done")/5 -> 0
C21: =IF(C20=1,"You did it. You know your numbers. Head to your Dashboard ✨","Step "&(COUNTIF(E7:E15,"✓ done")+1)&" of 5. You're doing great.") -> Step 1 of 5. You're doing great.
C23: Then, once a week: your money minute. Two numbers, about 60 seconds.
C24: Paid for a client coffee, parking or materials? Pop it in 'Client extras' when you can.
C26: The Money Mirror helps you see your numbers. It isn't tax, legal or financial advice. For that, talk to an accountant or financial adviser.

Sheet Dashboard
B2: =IF(YourName="","Your money, at a glance.","Hi "&YourName&". Here's where you are.") -> Your money, at a glance.
B3: ="Updated "&TEXT(TODAY(),"dddd d mmmm") -> Updated Thursday 29 October
B6: SAFE TO SPEND THIS MONTH
B7: =C50 -> 0
B10: =IF(C50>=0,"You can breathe. This is yours to use this month.",IF(C50>=-C53,"You're into your cushion. Go gently this month.","Pause big spends for now. Start with what's owed to you →")) -> You can breathe. This is yours to use this month.
B13: Balance today | C13: Money in this month | D13: Fixed costs still to pay | E13: Set aside for tax
B14: =C41 -> 0 | C14: =C42 -> 0 | D14: =C45 -> 0 | E14: =C46 -> 0
B17: OWED TO YOU
B18: =C47 -> 0 | C18: =IF(C48=0,"Nothing waiting. Lovely.",C48&IF(C48=1," invoice"," invoices")&" waiting"&IF(C49>0,", "&C49&" overdue. A gentle nudge today?",". All on time.")) -> Nothing waiting. Lovely.
B20: COMING UP: YEARLY COSTS
B21: =C57 -> 0 | C21: =IF(C54=0,"No yearly costs added yet. Insurance, software, memberships? Add them in Fixed costs.","Next: "&C56&" on "&TEXT(C54,"d mmm")&", "&IF(C54-TODAY()=1,"tomorrow","in "&(C54-TODAY())&" days")&". Yearly costs total "&TEXT(C58,"#,##0")&", about "&TEXT(C58/12,"#,##0")&" a month to put aside.") -> No yearly costs added yet. Insurance, software, memberships? Add them in Fixed costs.
B23: CLIENT EXTRAS THIS MONTH
B24: =C59 -> 0 | C24: =IF(C60=0,"None logged this month. Coffee, parking, materials for clients? Add them in Client extras.",C60&IF(C60=1," cost"," costs")&" included in your fees, mostly "&LOWER(C66)&".") -> None logged this month. Coffee, parking, materials for clients? Add them in Client extras.
B26: YOUR MONEY MINUTE
B27: =IF(C51=-1,"Your first money minute is waiting. Two numbers, about 60 seconds.",IF(C51<=7,"On track ✓ Last check-in "&IF(C51=0,"today",C51&IF(C51=1," day"," days")&" ago")&". "&C52&" this month.","It's been "&C51&" days. One minute, two numbers. You've got this.")) -> Your first money minute is waiting. Two numbers, about 60 seconds.
B30: Safe to spend = balance today − fixed costs still to pay this month (monthly, plus any yearly ones due this month) − tax to set aside − your comfort cushion.
B31: It's a guide to help you see clearly, not financial advice.
B40: Behind the scenes (no need to touch)
B41: Balance | C41: =IF(COUNT('Money minute'!B8:B107)=0,N(StartBalance),INDEX('Money minute'!C8:C107,MATCH(MAX('Money minute'!B8:B107),'Money minute'!B8:B107,0))) -> 0
B42: Money in this month | C42: =SUMPRODUCT(('Owed to you'!E8:E107>=(EOMONTH(TODAY(),-1)+1))*('Owed to you'!E8:E107<=EOMONTH(TODAY(),0))*'Owed to you'!C8:C107)+SUMPRODUCT(('Money minute'!B8:B107>=(EOMONTH(TODAY(),-1)+1))*('Money minute'!B8:B107<=EOMONTH(TODAY(),0))*'Money minute'!D8:D107) -> 0
B43: Monthly still to pay | C43: =SUMPRODUCT(('Fixed costs'!D8:D107<>"Yearly")*('Fixed costs'!E8:E107>DAY(TODAY()))*'Fixed costs'!C8:C107) -> 0
B44: Yearly still to pay this month | C44: =SUMPRODUCT(('Fixed costs'!D8:D107="Yearly")*('Fixed costs'!I8:I107=MONTH(TODAY()))*('Fixed costs'!E8:E107>DAY(TODAY()))*'Fixed costs'!C8:C107) -> 0
B45: Fixed still to pay | C45: =C43+C44 -> 0
B46: Tax to set aside | C46: =ROUND(N(TaxRate)*C42,0) -> 0
B47: Owed to you | C47: =SUMPRODUCT(('Owed to you'!E8:E107="")*'Owed to you'!C8:C107) -> 0
B48: Invoices waiting | C48: =SUMPRODUCT(('Owed to you'!E8:E107="")*('Owed to you'!C8:C107<>"")) -> 0
B49: Overdue | C49: =SUMPRODUCT(('Owed to you'!E8:E107="")*('Owed to you'!C8:C107<>"")*('Owed to you'!D8:D107<>"")*('Owed to you'!D8:D107<TODAY())) -> 0
B50: Safe to spend | C50: =C41-C45-C46-N(Cushion) -> 0
B51: Days since money minute | C51: =IF(COUNT('Money minute'!B8:B107)=0,-1,TODAY()-MAX('Money minute'!B8:B107)) -> -1
B52: Money minutes this month | C52: =COUNTIFS('Money minute'!B8:B107,">="&(EOMONTH(TODAY(),-1)+1),'Money minute'!B8:B107,"<="&EOMONTH(TODAY(),0)) -> 0
B53: Cushion | C53: =N(Cushion) -> 0
B54: Next yearly date | C54: =_xlfn.MINIFS('Fixed costs'!H8:H107,'Fixed costs'!D8:D107,"Yearly") -> 0
B55: Next yearly row | C55: =IF(C54=0,0,SUMPRODUCT(MAX(('Fixed costs'!D8:D107="Yearly")*('Fixed costs'!H8:H107=C54)*(ROW('Fixed costs'!H8:H107)-7)))) -> 0
B56: Next yearly what | C56: =IF(C55=0,"",INDEX('Fixed costs'!B8:B107,C55))
B57: Next yearly amount | C57: =IF(C55=0,0,INDEX('Fixed costs'!C8:C107,C55)) -> 0
B58: Yearly costs total | C58: =SUMPRODUCT(('Fixed costs'!D8:D107="Yearly")*'Fixed costs'!C8:C107) -> 0
B59: Client extras this month | C59: =SUMPRODUCT(('Client extras'!B8:B107>=(EOMONTH(TODAY(),-1)+1))*('Client extras'!B8:B107<=EOMONTH(TODAY(),0))*'Client extras'!F8:F107) -> 0
B60: Client extras count this month | C60: =SUMPRODUCT(('Client extras'!B8:B107>=(EOMONTH(TODAY(),-1)+1))*('Client extras'!B8:B107<=EOMONTH(TODAY(),0))*('Client extras'!F8:F107<>"")) -> 0
B61: Extras: Meetings & hospitality | C61: =SUMPRODUCT(('Client extras'!B8:B107>=(EOMONTH(TODAY(),-1)+1))*('Client extras'!B8:B107<=EOMONTH(TODAY(),0))*('Client extras'!E8:E107="Meetings & hospitality")*'Client extras'!F8:F107) -> 0
B62: Extras: Travel & parking | C62: =SUMPRODUCT(('Client extras'!B8:B107>=(EOMONTH(TODAY(),-1)+1))*('Client extras'!B8:B107<=EOMONTH(TODAY(),0))*('Client extras'!E8:E107="Travel & parking")*'Client extras'!F8:F107) -> 0
...

Sheet Money minute
B2: Your money minute
B3: Once a week. Open your bank app, type today's date and balance. Done.
B4: Dates: type them the way you normally do, or double-click a date box for a calendar.
B6: Date | C6: Balance today | D6: Other money in* | E6: A note to yourself (optional)
B7: e.g. 3 Nov 2026 | C7: 4,250 | D7: 0 | E7: Felt okay. Chased Studio Luna.
B109: * Money that came in this week that isn't one of your invoices (a sale, a refund, a one-off job).

Sheet Owed to you
B2: Owed to you
B3: Every invoice you've sent. When one gets paid, just type the date. That's it.
B4: Dates: type them the way you normally do, or double-click a date box for a calendar.
B6: Client | C6: Amount | D6: Due date | E6: Paid on | F6: Status
B7: e.g. Studio Luna | C7: 1,200 | D7: 15 Nov 2026 | E7: (leave empty until paid)
F8: =IF(C8="","",IF(E8<>"","paid ✓ — nice",IF(D8="","waiting",IF(D8<TODAY(),"overdue "&(TODAY()-D8)&" days — chase gently","due in "&(D8-TODAY())&" days"))))
F9: =IF(C9="","",IF(E9<>"","paid ✓ — nice",IF(D9="","waiting",IF(D9<TODAY(),"overdue "&(TODAY()-D9)&" days — chase gently","due in "&(D9-TODAY())&" days"))))
F10: =IF(C10="","",IF(E10<>"","paid ✓ — nice",IF(D10="","waiting",IF(D10<TODAY(),"overdue "&(TODAY()-D10)&" days — chase gently","due in "&(D10-TODAY())&" days"))))
F11: =IF(C11="","",IF(E11<>"","paid ✓ — nice",IF(D11="","waiting",IF(D11<TODAY(),"overdue "&(TODAY()-D11)&" days — chase gently","due in "&(D11-TODAY())&" days"))))
F12: =IF(C12="","",IF(E12<>"","paid ✓ — nice",IF(D12="","waiting",IF(D12<TODAY(),"overdue "&(TODAY()-D12)&" days — chase gently","due in "&(D12-TODAY())&" days"))))
F13: =IF(C13="","",IF(E13<>"","paid ✓ — nice",IF(D13="","waiting",IF(D13<TODAY(),"overdue "&(TODAY()-D13)&" days — chase gently","due in "&(D13-TODAY())&" days"))))
F14: =IF(C14="","",IF(E14<>"","paid ✓ — nice",IF(D14="","waiting",IF(D14<TODAY(),"overdue "&(TODAY()-D14)&" days — chase gently","due in "&(D14-TODAY())&" days"))))
F15: =IF(C15="","",IF(E15<>"","paid ✓ — nice",IF(D15="","waiting",IF(D15<TODAY(),"overdue "&(TODAY()-D15)&" days — chase gently","due in "&(D15-TODAY())&" days"))))
F16: =IF(C16="","",IF(E16<>"","paid ✓ — nice",IF(D16="","waiting",IF(D16<TODAY(),"overdue "&(TODAY()-D16)&" days — chase gently","due in "&(D16-TODAY())&" days"))))
F17: =IF(C17="","",IF(E17<>"","paid ✓ — nice",IF(D17="","waiting",IF(D17<TODAY(),"overdue "&(TODAY()-D17)&" days — chase gently","due in "&(D17-TODAY())&" days"))))
F18: =IF(C18="","",IF(E18<>"","paid ✓ — nice",IF(D18="","waiting",IF(D18<TODAY(),"overdue "&(TODAY()-D18)&" days — chase gently","due in "&(D18-TODAY())&" days"))))
F19: =IF(C19="","",IF(E19<>"","paid ✓ — nice",IF(D19="","waiting",IF(D19<TODAY(),"overdue "&(TODAY()-D19)&" days — chase gently","due in "&(D19-TODAY())&" days"))))
... F107: =IF(C107="","",IF(E107<>"","paid ✓ — nice",IF(D107="","waiting",IF(D107<TODAY(),"overdue "&(TODAY()-D107)&" days — chase gently","due in "&(D107-TODAY())&" days"))))

Sheet Client extras
B2: Client extras
B3: Costs that are included in your fee, not billed separately: the coffee, the parking, the fonts you buy for them.
B4: Add them when they happen, or catch up during your money minute. Dates: type them the way you normally do, or double-click a date box for a calendar.
B6: Date | C6: What it was | D6: Client | E6: Type | F6: Amount
B7: e.g. 4 Nov 2026 | C7: Coffee at kick-off meeting | D7: Studio Luna | E7: Meetings & hospitality | F7: 18
B109: These are already out of your bank balance, so they're not taken off 'safe to spend' twice. They're here so you can see where money goes.

Sheet Fixed costs
B2: Fixed costs
B3: What leaves no matter what, every month or once a year. Add them once; you rarely touch this again.
B6: What it is | C6: Amount each time | D6: How often | E6: Day it leaves (1–31) | F6: Month (yearly costs only) | G6: This month | H6: Next time
B7: e.g. Insurance | C7: 1,200 | D7: Yearly | E7: 26 | F7: Jul
G8: =IF(OR(C8="",E8=""),"",IF(D8="Yearly",IF(F8="","pick a month →",IF(I8=MONTH(TODAY()),IF(E8>DAY(TODAY()),"still to pay","paid ✓"),"not this month")),IF(E8>DAY(TODAY()),"still to pay","paid ✓"))) | H8: =IF(OR(C8="",E8=""),"",IF(D8="Yearly",IF(F8="","",IF(DATE(YEAR(TODAY()),I8,E8)>TODAY(),DATE(YEAR(TODAY()),I8,E8),DATE(YEAR(TODAY())+1,I8,E8))),IF(E8>DAY(TODAY()),DATE(YEAR(TODAY()),MONTH(TODAY()),E8),DATE(YEAR(TODAY()),MONTH(TODAY())+1,E8)))) | I8: =IF(F8="","",MATCH(F8,{"Jan","Feb","Mar","Apr","May","Jun","Jul","Aug","Sep","Oct","Nov","Dec"},0))
G9: =IF(OR(C9="",E9=""),"",IF(D9="Yearly",IF(F9="","pick a month →",IF(I9=MONTH(TODAY()),IF(E9>DAY(TODAY()),"still to pay","paid ✓"),"not this month")),IF(E9>DAY(TODAY()),"still to pay","paid ✓"))) | H9: =IF(OR(C9="",E9=""),"",IF(D9="Yearly",IF(F9="","",IF(DATE(YEAR(TODAY()),I9,E9)>TODAY(),DATE(YEAR(TODAY()),I9,E9),DATE(YEAR(TODAY())+1,I9,E9))),IF(E9>DAY(TODAY()),DATE(YEAR(TODAY()),MONTH(TODAY()),E9),DATE(YEAR(TODAY()),MONTH(TODAY())+1,E9)))) | I9: =IF(F9="","",MATCH(F9,{"Jan","Feb","Mar","Apr","May","Jun","Jul","Aug","Sep","Oct","Nov","Dec"},0))
G10: =IF(OR(C10="",E10=""),"",IF(D10="Yearly",IF(F10="","pick a month →",IF(I10=MONTH(TODAY()),IF(E10>DAY(TODAY()),"still to pay","paid ✓"),"not this month")),IF(E10>DAY(TODAY()),"still to pay","paid ✓"))) | H10: =IF(OR(C10="",E10=""),"",IF(D10="Yearly",IF(F10="","",IF(DATE(YEAR(TODAY()),I10,E10)>TODAY(),DATE(YEAR(TODAY()),I10,E10),DATE(YEAR(TODAY())+1,I10,E10))),IF(E10>DAY(TODAY()),DATE(YEAR(TODAY()),MONTH(TODAY()),E10),DATE(YEAR(TODAY()),MONTH(TODAY())+1,E10)))) | I10: =IF(F10="","",MATCH(F10,{"Jan","Feb","Mar","Apr","May","Jun","Jul","Aug","Sep","Oct","Nov","Dec"},0))
G11: =IF(OR(C11="",E11=""),"",IF(D11="Yearly",IF(F11="","pick a month →",IF(I11=MONTH(TODAY()),IF(E11>DAY(TODAY()),"still to pay","paid ✓"),"not this month")),IF(E11>DAY(TODAY()),"still to pay","paid ✓"))) | H11: =IF(OR(C11="",E11=""),"",IF(D11="Yearly",IF(F11="","",IF(DATE(YEAR(TODAY()),I11,E11)>TODAY(),DATE(YEAR(TODAY()),I11,E11),DATE(YEAR(TODAY())+1,I11,E11))),IF(E11>DAY(TODAY()),DATE(YEAR(TODAY()),MONTH(TODAY()),E11),DATE(YEAR(TODAY()),MONTH(TODAY())+1,E11)))) | I11: =IF(F11="","",MATCH(F11,{"Jan","Feb","Mar","Apr","May","Jun","Jul","Aug","Sep","Oct","Nov","Dec"},0))
G12: =IF(OR(C12="",E12=""),"",IF(D12="Yearly",IF(F12="","pick a month →",IF(I12=MONTH(TODAY()),IF(E12>DAY(TODAY()),"still to pay","paid ✓"),"not this month")),IF(E12>DAY(TODAY()),"still to pay","paid ✓"))) | H12: =IF(OR(C12="",E12=""),"",IF(D12="Yearly",IF(F12="","",IF(DATE(YEAR(TODAY()),I12,E12)>TODAY(),DATE(YEAR(TODAY()),I12,E12),DATE(YEAR(TODAY())+1,I12,E12))),IF(E12>DAY(TODAY()),DATE(YEAR(TODAY()),MONTH(TODAY()),E12),DATE(YEAR(TODAY()),MONTH(TODAY())+1,E12)))) | I12: =IF(F12="","",MATCH(F12,{"Jan","Feb","Mar","Apr","May","Jun","Jul","Aug","Sep","Oct","Nov","Dec"},0))
G13: =IF(OR(C13="",E13=""),"",IF(D13="Yearly",IF(F13="","pick a month →",IF(I13=MONTH(TODAY()),IF(E13>DAY(TODAY()),"still to pay","paid ✓"),"not this month")),IF(E13>DAY(TODAY()),"still to pay","paid ✓"))) | H13: =IF(OR(C13="",E13=""),"",IF(D13="Yearly",IF(F13="","",IF(DATE(YEAR(TODAY()),I13,E13)>TODAY(),DATE(YEAR(TODAY()),I13,E13),DATE(YEAR(TODAY())+1,I13,E13))),IF(E13>DAY(TODAY()),DATE(YEAR(TODAY()),MONTH(TODAY()),E13),DATE(YEAR(TODAY()),MONTH(TODAY())+1,E13)))) | I13: =IF(F13="","",MATCH(F13,{"Jan","Feb","Mar","Apr","May","Jun","Jul","Aug","Sep","Oct","Nov","Dec"},0))
G14: =IF(OR(C14="",E14=""),"",IF(D14="Yearly",IF(F14="","pick a month →",IF(I14=MONTH(TODAY()),IF(E14>DAY(TODAY()),"still to pay","paid ✓"),"not this month")),IF(E14>DAY(TODAY()),"still to pay","paid ✓"))) | H14: =IF(OR(C14="",E14=""),"",IF(D14="Yearly",IF(F14="","",IF(DATE(YEAR(TODAY()),I14,E14)>TODAY(),DATE(YEAR(TODAY()),I14,E14),DATE(YEAR(TODAY())+1,I14,E14))),IF(E14>DAY(TODAY()),DATE(YEAR(TODAY()),MONTH(TODAY()),E14),DATE(YEAR(TODAY()),MONTH(TODAY())+1,E14)))) | I14: =IF(F14="","",MATCH(F14,{"Jan","Feb","Mar","Apr","May","Jun","Jul","Aug","Sep","Oct","Nov","Dec"},0))
G15: =IF(OR(C15="",E15=""),"",IF(D15="Yearly",IF(F15="","pick a month →",IF(I15=MONTH(TODAY()),IF(E15>DAY(TODAY()),"still to pay","paid ✓"),"not this month")),IF(E15>DAY(TODAY()),"still to pay","paid ✓"))) | H15: =IF(OR(C15="",E15=""),"",IF(D15="Yearly",IF(F15="","",IF(DATE(YEAR(TODAY()),I15,E15)>TODAY(),DATE(YEAR(TODAY()),I15,E15),DATE(YEAR(TODAY())+1,I15,E15))),IF(E15>DAY(TODAY()),DATE(YEAR(TODAY()),MONTH(TODAY()),E15),DATE(YEAR(TODAY()),MONTH(TODAY())+1,E15)))) | I15: =IF(F15="","",MATCH(F15,{"Jan","Feb","Mar","Apr","May","Jun","Jul","Aug","Sep","Oct","Nov","Dec"},0))
G16: =IF(OR(C16="",E16=""),"",IF(D16="Yearly",IF(F16="","pick a month →",IF(I16=MONTH(TODAY()),IF(E16>DAY(TODAY()),"still to pay","paid ✓"),"not this month")),IF(E16>DAY(TODAY()),"still to pay","paid ✓"))) | H16: =IF(OR(C16="",E16=""),"",IF(D16="Yearly",IF(F16="","",IF(DATE(YEAR(TODAY()),I16,E16)>TODAY(),DATE(YEAR(TODAY()),I16,E16),DATE(YEAR(TODAY())+1,I16,E16))),IF(E16>DAY(TODAY()),DATE(YEAR(TODAY()),MONTH(TODAY()),E16),DATE(YEAR(TODAY()),MONTH(TODAY())+1,E16)))) | I16: =IF(F16="","",MATCH(F16,{"Jan","Feb","Mar","Apr","May","Jun","Jul","Aug","Sep","Oct","Nov","Dec"},0))
G17: =IF(OR(C17="",E17=""),"",IF(D17="Yearly",IF(F17="","pick a month →",IF(I17=MONTH(TODAY()),IF(E17>DAY(TODAY()),"still to pay","paid ✓"),"not this month")),IF(E17>DAY(TODAY()),"still to pay","paid ✓"))) | H17: =IF(OR(C17="",E17=""),"",IF(D17="Yearly",IF(F17="","",IF(DATE(YEAR(TODAY()),I17,E17)>TODAY(),DATE(YEAR(TODAY()),I17,E17),DATE(YEAR(TODAY())+1,I17,E17))),IF(E17>DAY(TODAY()),DATE(YEAR(TODAY()),MONTH(TODAY()),E17),DATE(YEAR(TODAY()),MONTH(TODAY())+1,E17)))) | I17: =IF(F17="","",MATCH(F17,{"Jan","Feb","Mar","Apr","May","Jun","Jul","Aug","Sep","Oct","Nov","Dec"},0))
G18: =IF(OR(C18="",E18=""),"",IF(D18="Yearly",IF(F18="","pick a month →",IF(I18=MONTH(TODAY()),IF(E18>DAY(TODAY()),"still to pay","paid ✓"),"not this month")),IF(E18>DAY(TODAY()),"still to pay","paid ✓"))) | H18: =IF(OR(C18="",E18=""),"",IF(D18="Yearly",IF(F18="","",IF(DATE(YEAR(TODAY()),I18,E18)>TODAY(),DATE(YEAR(TODAY()),I18,E18),DATE(YEAR(TODAY())+1,I18,E18))),IF(E18>DAY(TODAY()),DATE(YEAR(TODAY()),MONTH(TODAY()),E18),DATE(YEAR(TODAY()),MONTH(TODAY())+1,E18)))) | I18: =IF(F18="","",MATCH(F18,{"Jan","Feb","Mar","Apr","May","Jun","Jul","Aug","Sep","Oct","Nov","Dec"},0))
G19: =IF(OR(C19="",E19=""),"",IF(D19="Yearly",IF(F19="","pick a month →",IF(I19=MONTH(TODAY()),IF(E19>DAY(TODAY()),"still to pay","paid ✓"),"not this month")),IF(E19>DAY(TODAY()),"still to pay","paid ✓"))) | H19: =IF(OR(C19="",E19=""),"",IF(D19="Yearly",IF(F19="","",IF(DATE(YEAR(TODAY()),I19,E19)>TODAY(),DATE(YEAR(TODAY()),I19,E19),DATE(YEAR(TODAY())+1,I19,E19))),IF(E19>DAY(TODAY()),DATE(YEAR(TODAY()),MONTH(TODAY()),E19),DATE(YEAR(TODAY()),MONTH(TODAY())+1,E19)))) | I19: =IF(F19="","",MATCH(F19,{"Jan","Feb","Mar","Apr","May","Jun","Jul","Aug","Sep","Oct","Nov","Dec"},0))
... G107: =IF(OR(C107="",E107=""),"",IF(D107="Yearly",IF(F107="","pick a month →",IF(I107=MONTH(TODAY()),IF(E107>DAY(TODAY()),"still to pay","paid ✓"),"not this month")),IF(E107>DAY(TODAY()),"still to pay","paid ✓"))) | H107: =IF(OR(C107="",E107=""),"",IF(D107="Yearly",IF(F107="","",IF(DATE(YEAR(TODAY()),I107,E107)>TODAY(),DATE(YEAR(TODAY()),I107,E107),DATE(YEAR(TODAY())+1,I107,E107))),IF(E107>DAY(TODAY()),DATE(YEAR(TODAY()),MONTH(TODAY()),E107),DATE(YEAR(TODAY()),MONTH(TODAY())+1,E107)))) | I107: =IF(F107="","",MATCH(F107,{"Jan","Feb","Mar","Apr","May","Jun","Jul","Aug","Sep","Oct","Nov","Dec"},0))
B109: If 'How often' is empty, it counts as monthly.
